sample_data_in.csv
timestamp,order_id,instrument,side,type,quantity,price,action
1749282470069676785,1,INST034,BUY,MARKET,995,0,NEW
1749282470069681831,1,INST034,BUY,MARKET,995,0,CANCEL
1749282470069687704,2,INST059,SELL,MARKET,495,0,NEW
1749282470069689679,3,INST053,SELL,MARKET,185,0,NEW
1749282470069697648,4,INST008,BUY,LIMIT,245,119.67,NEW
1749282470069703448,5,INST040,BUY,LIMIT,275,242.35,NEW
1749282470069705683,6,INST196,BUY,LIMIT,720,430.14,NEW
1749282470069709734,7,INST168,SELL,MARKET,565,0,NEW
1749282470069716899,8,INST053,BUY,MARKET,50,0,NEW
1749282470069725194,9,INST185,SELL,MARKET,995,0,NEW
1749282470069728431,10,INST002,BUY,MARKET,745,0,NEW
1749282470069730065,6,INST196,BUY,LIMIT,620,426.08,MODIFY
1749282470069730253,11,INST074,SELL,MARKET,200,0,NEW
1749282470069739589,2,INST059,SELL,MARKET,495,0,CANCEL
1749282470069747999,6,INST196,BUY,LIMIT,720,0,CANCEL
1749282470069752016,12,INST037,BUY,MARKET,440,0,NEW
1749282470069756077,13,INST098,BUY,LIMIT,195,291.58,NEW
1749282470069759076,7,INST168,SELL,LIMIT,950,427.49,MODIFY
1749282470069761356,14,INST049,SELL,MARKET,65,0,NEW
1749282470069762278,14,INST049,SELL,MARKET,65,0,CANCEL
1749282470069764528,10,INST002,BUY,MARKET,745,0,CANCEL
1749282470069765740,15,INST121,BUY,MARKET,585,0,NEW
1749282470069775462,16,INST146,BUY,MARKET,960,0,NEW
1749282470069778035,17,INST119,SELL,MARKET,505,0,NEW
1749282470069783301,17,INST119,SELL,LIMIT,165,482.44,MODIFY
1749282470069785395,18,INST171,BUY,MARKET,940,0,NEW
1749282470069792152,19,INST100,BUY,MARKET,585,0,NEW
1749282470069798294,20,INST198,BUY,LIMIT,235,162.69,NEW
1749282470069801499,21,INST186,SELL,MARKET,700,0,NEW
1749282470069809352,22,INST064,SELL,MARKET,650,0,NEW
1749282470069812061,7,INST168,SELL,MARKET,565,0,CANCEL
1749282470069813769,20,INST198,BUY,LIMIT,575,155.58,MODIFY
1749282470069823284,23,INST061,BUY,MARKET,675,0,NEW
1749282470069827879,24,INST060,SELL,MARKET,770,0,NEW
1749282470069833138,25,INST036,BUY,LIMIT,565,326.55,NEW
1749282470069837070,26,INST137,BUY,LIMIT,455,381.32,NEW
1749282470069843902,5,INST040,BUY,LIMIT,470,236.08,MODIFY
1749282470069848796,9,INST185,SELL,LIMIT,505,399.23,MODIFY
1749282470069856772,27,INST136,BUY,MARKET,310,0,NEW
1749282470069859610,28,INST061,BUY,LIMIT,30,384.18,NEW
1749282470069864256,5,INST040,BUY,LIMIT,275,253.82,MODIFY
1749282470069871399,29,INST021,SELL,LIMIT,350,142.44,NEW
1749282470069873795,30,INST074,BUY,MARKET,530,0,NEW
1749282470069877128,31,INST198,SELL,MARKET,930,0,NEW
1749282470069884081,32,INST117,SELL,LIMIT,690,125.87,NEW
1749282470069893625,5,INST040,BUY,LIMIT,320,247.76,MODIFY
1749282470069896335,33,INST035,SELL,MARKET,575,0,NEW
1749282470069900647,34,INST086,BUY,MARKET,760,0,NEW
1749282470069908314,11,INST074,SELL,MARKET,200,0,CANCEL
1749282470069909777,35,INST178,SELL,LIMIT,265,246.70,NEW
1749282470069909893,36,INST077,SELL,LIMIT,485,371.69,NEW
1749282470069918076,37,INST146,BUY,MARKET,925,0,NEW
1749282470069920709,28,INST061,BUY,LIMIT,370,380.94,MODIFY
1749282470069928749,38,INST191,SELL,LIMIT,585,304.68,NEW
1749282470069937198,39,INST068,SELL,MARKET,875,0,NEW
1749282470069937327,4,INST008,BUY,LIMIT,465,116.32,MODIFY
1749282470069944849,24,INST060,SELL,LIMIT,5,281.37,MODIFY
1749282470069949308,22,INST064,SELL,MARKET,650,0,CANCEL
1749282470069954820,40,INST016,BUY,LIMIT,910,60.41,NEW
1749282470069963423,41,INST007,BUY,MARKET,290,0,NEW
1749282470069969892,42,INST092,BUY,LIMIT,690,347.48,NEW
1749282470069979070,43,INST062,SELL,LIMIT,845,82.84,NEW
1749282470069985291,44,INST111,BUY,LIMIT,165,288.65,NEW
1749282470069988431,45,INST059,BUY,MARKET,950,0,NEW
1749282470069994386,5,INST040,BUY,LIMIT,360,234.83,MODIFY
1749282470070001543,46,INST141,SELL,MARKET,30,0,NEW
1749282470070002450,29,INST021,SELL,LIMIT,350,0,CANCEL
1749282470070009551,47,INST177,BUY,LIMIT,20,145.86,NEW
1749282470070016167,19,INST100,BUY,LIMIT,560,491.70,MODIFY
1749282470070016810,35,INST178,SELL,LIMIT,25,255.50,MODIFY
1749282470070019906,20,INST198,BUY,LIMIT,235,0,CANCEL
1749282470070028338,48,INST020,SELL,LIMIT,65,166.67,NEW
1749282470070037336,23,INST061,BUY,LIMIT,5,70.27,MODIFY
1749282470070039108,46,INST141,SELL,LIMIT,345,183.01,MODIFY
1749282470070045489,49,INST068,BUY,MARKET,585,0,NEW
1749282470070046778,50,INST200,SELL,MARKET,350,0,NEW
1749282470070048480,39,INST068,SELL,LIMIT,300,298.37,MODIFY
1749282470070055566,51,INST177,BUY,MARKET,585,0,NEW
1749282470070062359,52,INST137,SELL,MARKET,305,0,NEW
1749282470070071984,32,INST117,SELL,LIMIT,995,123.52,MODIFY
1749282470070072223,53,INST126,SELL,LIMIT,90,183.24,NEW
1749282470070081502,54,INST053,BUY,LIMIT,975,495.96,NEW
1749282470070090345,55,INST178,BUY,LIMIT,625,178.79,NEW
1749282470070092474,56,INST164,BUY,MARKET,270,0,NEW
1749282470070093184,57,INST148,SELL,MARKET,530,0,NEW
1749282470070100054,58,INST184,BUY,MARKET,400,0,NEW
1749282470070105375,4,INST008,BUY,LIMIT,245,0,CANCEL
1749282470070111104,59,INST194,SELL,MARKET,90,0,NEW
1749282470070113669,60,INST018,BUY,MARKET,525,0,NEW
1749282470070120323,40,INST016,BUY,LIMIT,910,0,CANCEL
1749282470070126075,23,INST061,BUY,MARKET,675,0,CANCEL
1749282470070134473,61,INST136,SELL,LIMIT,335,192.01,NEW
1749282470070138230,36,INST077,SELL,LIMIT,665,353.42,MODIFY
1749282470070146896,62,INST164,SELL,LIMIT,845,199.77,NEW
1749282470070150701,36,INST077,SELL,LIMIT,5,356.04,MODIFY
1749282470070158732,63,INST116,SELL,MARKET,5,0,NEW
1749282470070165571,64,INST124,SELL,LIMIT,120,133.15,NEW
1749282470070175059,27,INST136,BUY,LIMIT,645,139.78,MODIFY
1749282470070184751,65,INST072,BUY,MARKET,755,0,NEW
1749282470070187750,66,INST060,BUY,MARKET,780,0,NEW
1749282470070190954,67,INST142,SELL,MARKET,150,0,NEW
1749282470070197513,68,INST148,BUY,LIMIT,925,142.55,NEW
1749282470070200150,69,INST038,SELL,MARKET,515,0,NEW
1749282470070200790,70,INST049,BUY,MARKET,980,0,NEW
1749282470070206484,15,INST121,BUY,MARKET,585,0,CANCEL
1749282470070209753,49,INST068,BUY,LIMIT,835,116.40,MODIFY
1749282470070217806,71,INST158,SELL,MARKET,550,0,NEW
1749282470070222132,72,INST192,SELL,LIMIT,620,168.79,NEW
1749282470070224335,62,INST164,SELL,LIMIT,995,192.48,MODIFY
1749282470070230172,70,INST049,BUY,LIMIT,540,405.52,MODIFY
1749282470070231449,73,INST071,BUY,LIMIT,270,252.32,NEW
1749282470070233746,74,INST064,BUY,LIMIT,290,393.37,NEW
1749282470070235200,75,INST006,BUY,LIMIT,745,104.52,NEW
1749282470070244455,76,INST080,SELL,LIMIT,115,101.82,NEW
1749282470070252568,77,INST060,BUY,LIMIT,460,247.75,NEW
1749282470070260798,59,INST194,SELL,LIMIT,795,110.55,MODIFY
1749282470070268432,78,INST040,SELL,MARKET,780,0,NEW
1749282470070270525,79,INST128,BUY,LIMIT,335,77.65,NEW
1749282470070274976,60,INST018,BUY,LIMIT,805,276.61,MODIFY
1749282470070283650,80,INST036,SELL,MARKET,245,0,NEW
1749282470070284046,81,INST008,SELL,LIMIT,160,295.98,NEW
1749282470070291692,82,INST090,SELL,MARKET,520,0,NEW
1749282470070294747,83,INST073,SELL,LIMIT,355,60.45,NEW
1749282470070304075,5,INST040,BUY,LIMIT,275,0,CANCEL
1749282470070313890,84,INST003,BUY,LIMIT,870,408.65,NEW
1749282470070319864,85,INST080,SELL,LIMIT,275,383.68,NEW
1749282470070325998,9,INST185,SELL,LIMIT,675,290.12,MODIFY
1749282470070332550,86,INST022,BUY,MARKET,630,0,NEW
1749282470070336709,81,INST008,SELL,LIMIT,190,308.65,MODIFY
1749282470070342648,87,INST041,BUY,MARKET,995,0,NEW
1749282470070349669,88,INST141,SELL,LIMIT,920,312.02,NEW
1749282470070350431,62,INST164,SELL,LIMIT,795,204.63,MODIFY
1749282470070355213,33,INST035,SELL,MARKET,575,0,CANCEL
1749282470070355496,89,INST019,BUY,LIMIT,370,121.88,NEW
1749282470070365284,90,INST075,BUY,MARKET,35,0,NEW
1749282470070374098,91,INST054,BUY,LIMIT,755,127.77,NEW
1749282470070381027,41,INST007,BUY,MARKET,290,0,CANCEL
1749282470070386764,84,INST003,BUY,LIMIT,280,399.73,MODIFY
1749282470070393106,39,INST068,SELL,LIMIT,430,390.16,MODIFY
1749282470070397590,92,INST150,BUY,LIMIT,710,436.36,NEW
1749282470070402969,93,INST026,BUY,LIMIT,130,238.33,NEW
1749282470070407632,94,INST163,SELL,LIMIT,330,255.15,NEW
