sample_data/expected_output.csv
timestamp,order_id,instrument,side,type,quantity,price,action,status,executed_quantity,execution_price,counterparty_id
1617278400000000000,1,AAPL,BUY,LIMIT,100,150.25,NEW,PENDING,0,0,0
1617278400000000100,2,AAPL,SELL,LIMIT,0,150.25,NEW,EXECUTED,50,150.25,1
1617278400000000100,1,AAPL,BUY,LIMIT,50,150.25,NEW,PARTIALLY_EXECUTED,50,150.25,2
1617278400000000200,3,AAPL,SELL,LIMIT,60,150.3,NEW,PENDING,0,0,0
1617278400000000300,4,AAPL,BUY,LIMIT,40,150.2,NEW,PENDING,0,0,0
1617278400000000400,1,AAPL,BUY,LIMIT,0,150.3,MODIFY,EXECUTED,50,150.3,3
1617278400000000400,3,AAPL,SELL,LIMIT,10,150.3,NEW,PARTIALLY_EXECUTED,50,150.3,1
1617278400000000500,3,AAPL,SELL,LIMIT,0,0,CANCEL,CANCELED,0,0,0
