sample_data/base_input.csv
timestamp , order_id , instrument , side , type , quantity , price , action
1617278400000000000 ,1 , AAPL , BUY , LIMIT ,100 ,150.25 , NEW
1617278400000000100 ,2 , AAPL , SELL , LIMIT ,50 ,150.25 , NEW
1617278400000000200 ,3 , AAPL , SELL , LIMIT ,60 ,150.30 , NEW
1617278400000000300 ,4 , AAPL , BUY , LIMIT ,40 ,150.20 , NEW
1617278400000000400 ,1 , AAPL , BUY , LIMIT ,100 ,150.30 , MODIFY
1617278400000000500 ,3 , AAPL , SELL , LIMIT ,60 ,0 , CANCEL
